Workbook

Sheet Início
A1: ROADMAP DE CURSOS & APRENDIZADO
A2: Pós-graduação · Concursos · Livros · Cursos de IA · Renda Extra — Sage Dreams · Calm & Natural
B5: NAVEGAÇÃO · CLIQUE PARA ABRIR
B6: Dashboard | E6: Roadmap | H6: Metas de Estudo | K6: Diário de Estudo
B7: Visão executiva, vencimentos urgentes e gráficos | E7: Linha do tempo de 12 meses (Gantt) | H7: Metas de horas, ritmo e mapa de calor | K7: Registro de cada sessão de estudo
B9: Pós-graduação | E9: Concurso | H9: Livros | K9: Cursos IA
B10: MBAs, especializações e extensões | E10: Preparatórios, banca e data da prova | H10: Biblioteca, páginas lidas e notas | K10: Inteligência artificial e automação
B12: Renda Extra | E12: Listas
B13: Cursos de renda e resultado mensal | E13: Listas das setas e prazo de alerta
B16: COMO USAR EM 6 PASSOS
B17: 1 | C17: Abra a aba da categoria e substitua a linha 10 (exemplo) pelo seu primeiro curso. Cada aba comporta 40 itens.
B18: 2 | C18: Preencha instituição, datas (compra, início, término previsto e vencimento do acesso), valor, login e senha.
B19: 3 | C19: Informe o total de aulas, disciplinas ou páginas e atualize o quanto já concluiu — o % de andamento é automático.
B20: 4 | C20: Escolha Status, Prioridade e Certificado pela seta da célula. Vencimento em branco = acesso vitalício.
B21: 5 | C21: Registre cada sessão no Diário de Estudo (linha 7 em diante, com o mesmo nome do curso) e defina metas em Metas de Estudo.
B22: 6 | C22: Acompanhe no Dashboard: previsão de término, risco de perder o acesso, custo por hora e ROI da renda extra — tudo automático.
B24: LEGENDA
B25: Célula branca | D25: Campo para preencher.
B26: Célula cinza-areia | D26: Fórmula automática — não edite nem apague.
B27: Em andamento | D27: Status em andamento · barra do Roadmap em verde-sálvia.
B28: Concluído | D28: Status concluído · barra do Roadmap em verde-escuro.
B29: ▲ A vencer | D29: Acesso com vencimento dentro do prazo de alerta (padrão 30 dias, editável em Listas).
B30: ■ Vencido | D30: Acesso expirado — priorize ou renove.
B32: IMPORTANTE
B33: • Previsão de término usa seu ritmo real desde a data de início; sem nenhuma aula/página concluída aparece “Sem ritmo”. “■ Estoura o acesso” = previsão depois do vencimento.
B34: • Não edite as células cinza-areia nem a aba Apoio: elas alimentam o Dashboard, o Roadmap e as Metas.
B35: • Segurança: planilha não é cofre. Prefira um gerenciador de senhas, use a coluna Senha só como lembrete e não compartilhe este arquivo.
B36: • As linhas de exemplo (cursos e diário) entram nos totais até serem substituídas ou apagadas. As metas de horas iniciais (20/20/8/15/10) são sugestões — ajuste em Metas de Estudo.
B37: • Mais de 40 itens? Copie uma linha inteira e use “Inserir células copiadas” ENTRE as linhas do meio da tabela, para fórmulas e gráficos acompanharem.

Sheet Dashboard
A1: DASHBOARD · ROADMAP DE APRENDIZADO
A2: Visão executiva de todas as categorias — tudo atualiza sozinho | K2: ← Voltar ao Início
B5: TOTAL DE ITENS | D5: EM ANDAMENTO | F5: CONCLUÍDOS | H5: INVESTIMENTO TOTAL | J5: PROGRESSO MÉDIO | L5: CERTIFICADOS EMITIDOS
B6: =C20 -> 5 | D6: =E20 -> 5 | F6: =F20 -> 0 | H6: =H20 -> 14933.9 | J6: =I20 -> 0.24944444 | L6: =M20 -> 0
B9: HORAS ESTUDADAS | D9: CUSTO MÉDIO POR HORA | F9: EM RISCO DE PERDER ACESSO | H9: ATRASADOS VS PLANO | J9: ROI · RENDA EXTRA | L9: PAYBACK MÉDIO (MESES)
B10: ='Diário de Estudo'!D5 -> 4.5 | D10: =IFERROR((SUMIF('Pós-graduação'!O10:O49,">0",'Pós-graduação'!F10:F49)+SUMIF(Concurso!Q10:Q49,">0",Concurso!H10:H49)+SUMIF(Livros!N10:N49,">0",Livros!H10:H49)+SUMIF('Cursos IA'!O10:O49,">0",'Cursos IA'!F10:F49)+SUMIF('Renda Extra'!O10:O49,">0",'Renda Extra'!F10:F49))/(SUM('Pós-graduação'!O10:O49)+SUM(Concurso!Q10:Q49)+SUM(Livros!N10:N49)+SUM('Cursos IA'!O10:O49)+SUM('Renda Extra'!O10:O49)),0) -> 2921.5333 | F10: =COUNTIF('Pós-graduação'!R10:R49,"*Estoura o acesso")+COUNTIF(Concurso!T10:T49,"*Estoura o acesso")+COUNTIF('Cursos IA'!R10:R49,"*Estoura o acesso")+COUNTIF('Renda Extra'!R10:R49,"*Estoura o acesso") -> 0 | H10: =COUNTIF('Pós-graduação'!R10:R49,"*Atrasado vs plano")+COUNTIF(Concurso!T10:T49,"*Atrasado vs plano")+COUNTIF(Livros!Q10:Q49,"*Atrasado vs plano")+COUNTIF('Cursos IA'!R10:R49,"*Atrasado vs plano")+COUNTIF('Renda Extra'!R10:R49,"*Atrasado vs plano") -> 1 | J10: =IFERROR((SUM('Renda Extra'!X10:X49)-SUM('Renda Extra'!F10:F49))/SUM('Renda Extra'!F10:F49),0) -> -0.39393939 | L10: =IFERROR(AVERAGE('Renda Extra'!Z10:Z49),"—") -> 0.975
B12: Atualizado em: | C12: =TODAY() -> 46298
B13: RESUMO POR CATEGORIA
B14: Categoria | C14: Itens | D14: Não iniciado | E14: Em andamento | F14: Concluído | G14: Pausado | H14: Investimento (R$) | I14: % médio | J14: Progresso | K14: A vencer | L14: Vencidos | M14: Certificados
B15: Pós-graduação | C15: =COUNTA('Pós-graduação'!B10:B49) -> 1 | D15: =COUNTIF('Pós-graduação'!S10:S49,D$14) -> 0 | E15: =COUNTIF('Pós-graduação'!S10:S49,E$14) -> 1 | F15: =COUNTIF('Pós-graduação'!S10:S49,F$14) -> 0 | G15: =COUNTIF('Pós-graduação'!S10:S49,G$14) -> 0 | H15: =SUM('Pós-graduação'!F10:F49) -> 12600 | I15: =IFERROR(AVERAGE('Pós-graduação'!N10:N49),0) -> 0.1 | J15: =REPT("█",MIN(10,ROUND(I15*10,0)))&REPT("░",10-MIN(10,ROUND(I15*10,0))) -> █░░░░░░░░░ | K15: =COUNTIF('Pós-graduação'!K10:K49,"*A vencer") -> 0 | L15: =COUNTIF('Pós-graduação'!K10:K49,"*Vencido") -> 0 | M15: =COUNTIF('Pós-graduação'!U10:U49,"Emitido") -> 0
B16: Concurso | C16: =COUNTA(Concurso!B10:B49) -> 1 | D16: =COUNTIF(Concurso!U10:U49,D$14) -> 0 | E16: =COUNTIF(Concurso!U10:U49,E$14) -> 1 | F16: =COUNTIF(Concurso!U10:U49,F$14) -> 0 | G16: =COUNTIF(Concurso!U10:U49,G$14) -> 0 | H16: =SUM(Concurso!H10:H49) -> 1490 | I16: =IFERROR(AVERAGE(Concurso!P10:P49),0) -> 0.25 | J16: =REPT("█",MIN(10,ROUND(I16*10,0)))&REPT("░",10-MIN(10,ROUND(I16*10,0))) -> ███░░░░░░░ | K16: =COUNTIF(Concurso!M10:M49,"*A vencer") -> 0 | L16: =COUNTIF(Concurso!M10:M49,"*Vencido") -> 0 | M16: =COUNTIF(Concurso!W10:W49,"Emitido") -> 0
B17: Livros | C17: =COUNTA(Livros!B10:B49) -> 1 | D17: =COUNTIF(Livros!R10:R49,D$14) -> 0 | E17: =COUNTIF(Livros!R10:R49,E$14) -> 1 | F17: =COUNTIF(Livros!R10:R49,F$14) -> 0 | G17: =COUNTIF(Livros!R10:R49,G$14) -> 0 | H17: =SUM(Livros!H10:H49) -> 49.9 | I17: =IFERROR(AVERAGE(Livros!M10:M49),0) -> 0.375 | J17: =REPT("█",MIN(10,ROUND(I17*10,0)))&REPT("░",10-MIN(10,ROUND(I17*10,0))) -> ████░░░░░░ | K17: — | L17: — | M17: —
B18: Cursos IA | C18: =COUNTA('Cursos IA'!B10:B49) -> 1 | D18: =COUNTIF('Cursos IA'!S10:S49,D$14) -> 0 | E18: =COUNTIF('Cursos IA'!S10:S49,E$14) -> 1 | F18: =COUNTIF('Cursos IA'!S10:S49,F$14) -> 0 | G18: =COUNTIF('Cursos IA'!S10:S49,G$14) -> 0 | H18: =SUM('Cursos IA'!F10:F49) -> 497 | I18: =IFERROR(AVERAGE('Cursos IA'!N10:N49),0) -> 0.3 | J18: =REPT("█",MIN(10,ROUND(I18*10,0)))&REPT("░",10-MIN(10,ROUND(I18*10,0))) -> ███░░░░░░░ | K18: =COUNTIF('Cursos IA'!K10:K49,"*A vencer") -> 0 | L18: =COUNTIF('Cursos IA'!K10:K49,"*Vencido") -> 0 | M18: =COUNTIF('Cursos IA'!U10:U49,"Emitido") -> 0
B19: Renda Extra | C19: =COUNTA('Renda Extra'!B10:B49) -> 1 | D19: =COUNTIF('Renda Extra'!S10:S49,D$14) -> 0 | E19: =COUNTIF('Renda Extra'!S10:S49,E$14) -> 1 | F19: =COUNTIF('Renda Extra'!S10:S49,F$14) -> 0 | G19: =COUNTIF('Renda Extra'!S10:S49,G$14) -> 0 | H19: =SUM('Renda Extra'!F10:F49) -> 297 | I19: =IFERROR(AVERAGE('Renda Extra'!N10:N49),0) -> 0.22222222 | J19: =REPT("█",MIN(10,ROUND(I19*10,0)))&REPT("░",10-MIN(10,ROUND(I19*10,0))) -> ██░░░░░░░░ | K19: =COUNTIF('Renda Extra'!K10:K49,"*A vencer") -> 0 | L19: =COUNTIF('Renda Extra'!K10:K49,"*Vencido") -> 0 | M19: =COUNTIF('Renda Extra'!U10:U49,"Emitido") -> 0
B20: TOTAL | C20: =SUM(C15:C19) -> 5 | D20: =SUM(D15:D19) -> 0 | E20: =SUM(E15:E19) -> 5 | F20: =SUM(F15:F19) -> 0 | G20: =SUM(G15:G19) -> 0 | H20: =SUM(H15:H19) -> 14933.9 | I20: =IFERROR(SUMPRODUCT(C15:C19,I15:I19)/C20,0) -> 0.24944444 | J20: =REPT("█",MIN(10,ROUND(I20*10,0)))&REPT("░",10-MIN(10,ROUND(I20*10,0))) -> ██░░░░░░░░ | K20: =SUM(K15:K19) -> 0 | L20: =SUM(L15:L19) -> 0 | M20: =SUM(M15:M19) -> 0
B22: VENCIMENTOS DE ACESSO · MAIS URGENTES PRIMEIRO | H22: METAS DE ESTUDO DO MÊS | M22: ='Metas de Estudo'!E5 -> 46296
B23: Categoria | C23: Item | F23: Vence em | G23: Dias | H23: Categoria | J23: Meta (h) | K23: Realizado | L23: % meta | M23: Progresso
B24: =IF(Apoio!$L$5="","",INDEX(Apoio!$A$5:$A$164,Apoio!$L$5)) -> Concurso | C24: =IF(Apoio!$L$5="","",INDEX(Apoio!$B$5:$B$164,Apoio!$L$5)) -> Curso Preparatório Completo (exemplo) | F24: =IF(Apoio!$L$5="","",INDEX(Apoio!$C$5:$C$164,Apoio!$L$5)) -> 46568 | G24: =IF(Apoio!$L$5="","",INDEX(Apoio!$D$5:$D$164,Apoio!$L$5)) -> 270 | H24: ='Metas de Estudo'!B13 -> Pós-graduação | J24: ='Metas de Estudo'!C13 -> 20 | K24: ='Metas de Estudo'!D13 -> 2 | L24: ='Metas de Estudo'!E13 -> 0.1 | M24: ='Metas de Estudo'!F13 -> █░░░░░░░░░
B25: =IF(Apoio!$L$6="","",INDEX(Apoio!$A$5:$A$164,Apoio!$L$6)) -> Renda Extra | C25: =IF(Apoio!$L$6="","",INDEX(Apoio!$B$5:$B$164,Apoio!$L$6)) -> Marketing de Afiliados do Zero (exemplo) | F25: =IF(Apoio!$L$6="","",INDEX(Apoio!$C$5:$C$164,Apoio!$L$6)) -> 46631 | G25: =IF(Apoio!$L$6="","",INDEX(Apoio!$D$5:$D$164,Apoio!$L$6)) -> 333 | H25: ='Metas de Estudo'!B14 -> Concurso | J25: ='Metas de Estudo'!C14 -> 20 | K25: ='Metas de Estudo'!D14 -> 0 | L25: ='Metas de Estudo'!E14 -> 0 | M25: ='Metas de Estudo'!F14 -> ░░░░░░░░░░
B26: =IF(Apoio!$L$7="","",INDEX(Apoio!$A$5:$A$164,Apoio!$L$7)) -> Cursos IA | C26: =IF(Apoio!$L$7="","",INDEX(Apoio!$B$5:$B$164,Apoio!$L$7)) -> Agentes de IA na Prática (exemplo) | F26: =IF(Apoio!$L$7="","",INDEX(Apoio!$C$5:$C$164,Apoio!$L$7)) -> 46642 | G26: =IF(Apoio!$L$7="","",INDEX(Apoio!$D$5:$D$164,Apoio!$L$7)) -> 344 | H26: ='Metas de Estudo'!B15 -> Livros | J26: ='Metas de Estudo'!C15 -> 8 | K26: ='Metas de Estudo'!D15 -> 1 | L26: ='Metas de Estudo'!E15 -> 0.125 | M26: ='Metas de Estudo'!F15 -> █░░░░░░░░░
B27: =IF(Apoio!$L$8="","",INDEX(Apoio!$A$5:$A$164,Apoio!$L$8)) -> Pós-graduação | C27: =IF(Apoio!$L$8="","",INDEX(Apoio!$B$5:$B$164,Apoio!$L$8)) -> MBA em Inteligência Artificial (exemplo) | F27: =IF(Apoio!$L$8="","",INDEX(Apoio!$C$5:$C$164,Apoio!$L$8)) -> 46997 | G27: =IF(Apoio!$L$8="","",INDEX(Apoio!$D$5:$D$164,Apoio!$L$8)) -> 699 | H27: ='Metas de Estudo'!B16 -> Cursos IA | J27: ='Metas de Estudo'!C16 -> 15 | K27: ='Metas de Estudo'!D16 -> 1.5 | L27: ='Metas de Estudo'!E16 -> 0.1 | M27: ='Metas de Estudo'!F16 -> █░░░░░░░░░
B28: =IF(Apoio!$L$9="","",INDEX(Apoio!$A$5:$A$164,Apoio!$L$9)) | C28: =IF(Apoio!$L$9="","",INDEX(Apoio!$B$5:$B$164,Apoio!$L$9)) | F28: =IF(Apoio!$L$9="","",INDEX(Apoio!$C$5:$C$164,Apoio!$L$9)) | G28: =IF(Apoio!$L$9="","",INDEX(Apoio!$D$5:$D$164,Apoio!$L$9)) | H28: ='Metas de Estudo'!B17 -> Renda Extra | J28: ='Metas de Estudo'!C17 -> 10 | K28: ='Metas de Estudo'!D17 -> 0 | L28: ='Metas de Estudo'!E17 -> 0 | M28: ='Metas de Estudo'!F17 -> ░░░░░░░░░░
B29: =IF(Apoio!$L$10="","",INDEX(Apoio!$A$5:$A$164,Apoio!$L$10)) | C29: =IF(Apoio!$L$10="","",INDEX(Apoio!$B$5:$B$164,Apoio!$L$10)) | F29: =IF(Apoio!$L$10="","",INDEX(Apoio!$C$5:$C$164,Apoio!$L$10)) | G29: =IF(Apoio!$L$10="","",INDEX(Apoio!$D$5:$D$164,Apoio!$L$10)) | H29: Dias estudados | J29: ='Metas de Estudo'!G8 -> 3
B30: =IF(Apoio!$L$11="","",INDEX(Apoio!$A$5:$A$164,Apoio!$L$11)) | C30: =IF(Apoio!$L$11="","",INDEX(Apoio!$B$5:$B$164,Apoio!$L$11)) | F30: =IF(Apoio!$L$11="","",INDEX(Apoio!$C$5:$C$164,Apoio!$L$11)) | G30: =IF(Apoio!$L$11="","",INDEX(Apoio!$D$5:$D$164,Apoio!$L$11)) | H30: Média por dia | J30: =IFERROR('Metas de Estudo'!D18/'Metas de Estudo'!G8,0) -> 1.5
B31: =IF(Apoio!$L$12="","",INDEX(Apoio!$A$5:$A$164,Apoio!$L$12)) | C31: =IF(Apoio!$L$12="","",INDEX(Apoio!$B$5:$B$164,Apoio!$L$12)) | F31: =IF(Apoio!$L$12="","",INDEX(Apoio!$C$5:$C$164,Apoio!$L$12)) | G31: =IF(Apoio!$L$12="","",INDEX(Apoio!$D$5:$D$164,Apoio!$L$12)) | H31: Total do mês | J31: ='Metas de Estudo'!D18 -> 4.5
B33: RISCO: PREVISÃO DE TÉRMINO DEPOIS DO VENCIMENTO | H33: ROI · CURSOS DE RENDA EXTRA
B34: Categoria | C34: Item | F34: Previsão | G34: Folga (dias) | H34: Curso | J34: Investido | K34: Receita acum. | L34: ROI | M34: Payback (m)
B35: =IF(Apoio!$N$5="","",INDEX(Apoio!$A$5:$A$164,Apoio!$N$5)) | C35: =IF(Apoio!$N$5="","Nenhum curso em risco — bom ritmo!",INDEX(Apoio!$B$5:$B$164,Apoio!$N$5)) -> Nenhum curso em risco — bom ritmo! | F35: =IF(Apoio!$N$5="","",INDEX(Apoio!$F$5:$F$164,Apoio!$N$5)) | G35: =IF(Apoio!$N$5="","",INDEX(Apoio!$G$5:$G$164,Apoio!$N$5)) | H35: =IF('Renda Extra'!$B10="","",'Renda Extra'!$B10) -> Marketing de Afiliados do Zero (exemplo) | J35: =IF($H35="","",'Renda Extra'!$F10) -> 297 | K35: =IF($H35="","",N('Renda Extra'!$X10)) -> 180 | L35: =IF($H35="","",'Renda Extra'!$Y10) -> -0.39393939 | M35: =IF($H35="","",'Renda Extra'!$Z10) -> 0.975
B36: =IF(Apoio!$N$6="","",INDEX(Apoio!$A$5:$A$164,Apoio!$N$6)) | C36: =IF(Apoio!$N$6="","",INDEX(Apoio!$B$5:$B$164,Apoio!$N$6)) | F36: =IF(Apoio!$N$6="","",INDEX(Apoio!$F$5:$F$164,Apoio!$N$6)) | G36: =IF(Apoio!$N$6="","",INDEX(Apoio!$G$5:$G$164,Apoio!$N$6)) | H36: =IF('Renda Extra'!$B11="","",'Renda Extra'!$B11) | J36: =IF($H36="","",'Renda Extra'!$F11) | K36: =IF($H36="","",N('Renda Extra'!$X11)) | L36: =IF($H36="","",'Renda Extra'!$Y11) | M36: =IF($H36="","",'Renda Extra'!$Z11)
B37: =IF(Apoio!$N$7="","",INDEX(Apoio!$A$5:$A$164,Apoio!$N$7)) | C37: =IF(Apoio!$N$7="","",INDEX(Apoio!$B$5:$B$164,Apoio!$N$7)) | F37: =IF(Apoio!$N$7="","",INDEX(Apoio!$F$5:$F$164,Apoio!$N$7)) | G37: =IF(Apoio!$N$7="","",INDEX(Apoio!$G$5:$G$164,Apoio!$N$7)) | H37: =IF('Renda Extra'!$B12="","",'Renda Extra'!$B12) | J37: =IF($H37="","",'Renda Extra'!$F12) | K37: =IF($H37="","",N('Renda Extra'!$X12)) | L37: =IF($H37="","",'Renda Extra'!$Y12) | M37: =IF($H37="","",'Renda Extra'!$Z12)
B38: =IF(Apoio!$N$8="","",INDEX(Apoio!$A$5:$A$164,Apoio!$N$8)) | C38: =IF(Apoio!$N$8="","",INDEX(Apoio!$B$5:$B$164,Apoio!$N$8)) | F38: =IF(Apoio!$N$8="","",INDEX(Apoio!$F$5:$F$164,Apoio!$N$8)) | G38: =IF(Apoio!$N$8="","",INDEX(Apoio!$G$5:$G$164,Apoio!$N$8)) | H38: =IF('Renda Extra'!$B13="","",'Renda Extra'!$B13) | J38: =IF($H38="","",'Renda Extra'!$F13) | K38: =IF($H38="","",N('Renda Extra'!$X13)) | L38: =IF($H38="","",'Renda Extra'!$Y13) | M38: =IF($H38="","",'Renda Extra'!$Z13)
B39: =IF(Apoio!$N$9="","",INDEX(Apoio!$A$5:$A$164,Apoio!$N$9)) | C39: =IF(Apoio!$N$9="","",INDEX(Apoio!$B$5:$B$164,Apoio!$N$9)) | F39: =IF(Apoio!$N$9="","",INDEX(Apoio!$F$5:$F$164,Apoio!$N$9)) | G39: =IF(Apoio!$N$9="","",INDEX(Apoio!$G$5:$G$164,Apoio!$N$9)) | H39: =IF('Renda Extra'!$B14="","",'Renda Extra'!$B14) | J39: =IF($H39="","",'Renda Extra'!$F14) | K39: =IF($H39="","",N('Renda Extra'!$X14)) | L39: =IF($H39="","",'Renda Extra'!$Y14) | M39: =IF($H39="","",'Renda Extra'!$Z14)
B76: “A vencer” usa o prazo de Listas (H6). Previsão de término = ritmo real (itens concluídos ÷ dias desde o início). Custo por hora = valor pago ÷ horas do Diário (use o mesmo nome do curso).

Sheet Roadmap
A1: ROADMAP · LINHA DO TEMPO
A2: Barras = início → término previsto (cor pelo status) · ▼ = mês do vencimento do acesso | Q2: ← Voltar ao Início
A5: Mês inicial: | B5: 46296 | C5: ← altere para deslocar a janela de 12 meses · mostra os 12 primeiros itens de cada aba
A7: Categoria | B7: Item | C7: Status | D7: Início | E7: Término | F7: Vence acesso | G7: % Andam. | H7: =$B$5 -> 46296 | I7: =EDATE(H7,1) -> 46327 | J7: =EDATE(I7,1) -> 46357 | K7: =EDATE(J7,1) -> 46388 | L7: =EDATE(K7,1) -> 46419 | M7: =EDATE(L7,1) -> 46447 | N7: =EDATE(M7,1) -> 46478 | O7: =EDATE(N7,1) -> 46508 | P7: =EDATE(O7,1) -> 46539 | ... S7: =EDATE(R7,1) -> 46631
A8: PÓS-GRADUAÇÃO
A9: =IF($B9="","","Pós-graduação") -> Pós-graduação | B9: =IF('Pós-graduação'!B10="","",'Pós-graduação'!B10) -> MBA em Inteligência Artificial (exemplo) | C9: =IF($B9="","",IF('Pós-graduação'!S10="","",'Pós-graduação'!S10)) -> Em andamento | D9: =IF($B9="","",IF('Pós-graduação'!G10="","",'Pós-graduação'!G10)) -> 46266 | E9: =IF($B9="","",IF('Pós-graduação'!H10<>"",'Pós-graduação'!H10,IF('Pós-graduação'!I10<>"",'Pós-graduação'!I10,""))) -> 46813 | F9: =IF($B9="","",IF('Pós-graduação'!I10="","",'Pós-graduação'!I10)) -> 46997 | G9: =IF($B9="","",'Pós-graduação'!N10) -> 0.1 | H9: =IF(OR($B9="",$F9=""),"",IF(AND($F9>=H$7,$F9<EDATE(H$7,1)),"▼","")) | I9: =IF(OR($B9="",$F9=""),"",IF(AND($F9>=I$7,$F9<EDATE(I$7,1)),"▼","")) | J9: =IF(OR($B9="",$F9=""),"",IF(AND($F9>=J$7,$F9<EDATE(J$7,1)),"▼","")) | K9: =IF(OR($B9="",$F9=""),"",IF(AND($F9>=K$7,$F9<EDATE(K$7,1)),"▼","")) | L9: =IF(OR($B9="",$F9=""),"",IF(AND($F9>=L$7,$F9<EDATE(L$7,1)),"▼","")) | M9: =IF(OR($B9="",$F9=""),"",IF(AND($F9>=M$7,$F9<EDATE(M$7,1)),"▼","")) | N9: =IF(OR($B9="",$F9=""),"",IF(AND($F9>=N$7,$F9<EDATE(N$7,1)),"▼","")) | O9: =IF(OR($B9="",$F9=""),"",IF(AND($F9>=O$7,$F9<EDATE(O$7,1)),"▼","")) | ... S9: =IF(OR($B9="",$F9=""),"",IF(AND($F9>=S$7,$F9<EDATE(S$7,1)),"▼",""))
A10: =IF($B10="","","Pós-graduação") | B10: =IF('Pós-graduação'!B11="","",'Pós-graduação'!B11) | C10: =IF($B10="","",IF('Pós-graduação'!S11="","",'Pós-graduação'!S11)) | D10: =IF($B10="","",IF('Pós-graduação'!G11="","",'Pós-graduação'!G11)) | E10: =IF($B10="","",IF('Pós-graduação'!H11<>"",'Pós-graduação'!H11,IF('Pós-graduação'!I11<>"",'Pós-graduação'!I11,""))) | F10: =IF($B10="","",IF('Pós-graduação'!I11="","",'Pós-graduação'!I11)) | G10: =IF($B10="","",'Pós-graduação'!N11) | H10: =IF(OR($B10="",$F10=""),"",IF(AND($F10>=H$7,$F10<EDATE(H$7,1)),"▼","")) | I10: =IF(OR($B10="",$F10=""),"",IF(AND($F10>=I$7,$F10<EDATE(I$7,1)),"▼","")) | J10: =IF(OR($B10="",$F10=""),"",IF(AND($F10>=J$7,$F10<EDATE(J$7,1)),"▼","")) | K10: =IF(OR($B10="",$F10=""),"",IF(AND($F10>=K$7,$F10<EDATE(K$7,1)),"▼","")) | L10: =IF(OR($B10="",$F10=""),"",IF(AND($F10>=L$7,$F10<EDATE(L$7,1)),"▼","")) | M10: =IF(OR($B10="",$F10=""),"",IF(AND($F10>=M$7,$F10<EDATE(M$7,1)),"▼","")) | N10: =IF(OR($B10="",$F10=""),"",IF(AND($F10>=N$7,$F10<EDATE(N$7,1)),"▼","")) | O10: =IF(OR($B10="",$F10=""),"",IF(AND($F10>=O$7,$F10<EDATE(O$7,1)),"▼","")) | ... S10: =IF(OR($B10="",$F10=""),"",IF(AND($F10>=S$7,$F10<EDATE(S$7,1)),"▼",""))
A11: =IF($B11="","","Pós-graduação") | B11: =IF('Pós-graduação'!B12="","",'Pós-graduação'!B12) | C11: =IF($B11="","",IF('Pós-graduação'!S12="","",'Pós-graduação'!S12)) | D11: =IF($B11="","",IF('Pós-graduação'!G12="","",'Pós-graduação'!G12)) | E11: =IF($B11="","",IF('Pós-graduação'!H12<>"",'Pós-graduação'!H12,IF('Pós-graduação'!I12<>"",'Pós-graduação'!I12,""))) | F11: =IF($B11="","",IF('Pós-graduação'!I12="","",'Pós-graduação'!I12)) | G11: =IF($B11="","",'Pós-graduação'!N12) | H11: =IF(OR($B11="",$F11=""),"",IF(AND($F11>=H$7,$F11<EDATE(H$7,1)),"▼","")) | I11: =IF(OR($B11="",$F11=""),"",IF(AND($F11>=I$7,$F11<EDATE(I$7,1)),"▼","")) | J11: =IF(OR($B11="",$F11=""),"",IF(AND($F11>=J$7,$F11<EDATE(J$7,1)),"▼","")) | K11: =IF(OR($B11="",$F11=""),"",IF(AND($F11>=K$7,$F11<EDATE(K$7,1)),"▼","")) | L11: =IF(OR($B11="",$F11=""),"",IF(AND($F11>=L$7,$F11<EDATE(L$7,1)),"▼","")) | M11: =IF(OR($B11="",$F11=""),"",IF(AND($F11>=M$7,$F11<EDATE(M$7,1)),"▼","")) | N11: =IF(OR($B11="",$F11=""),"",IF(AND($F11>=N$7,$F11<EDATE(N$7,1)),"▼","")) | O11: =IF(OR($B11="",$F11=""),"",IF(AND($F11>=O$7,$F11<EDATE(O$7,1)),"▼","")) | ... S11: =IF(OR($B11="",$F11=""),"",IF(AND($F11>=S$7,$F11<EDATE(S$7,1)),"▼",""))
A12: =IF($B12="","","Pós-graduação") | B12: =IF('Pós-graduação'!B13="","",'Pós-graduação'!B13) | C12: =IF($B12="","",IF('Pós-graduação'!S13="","",'Pós-graduação'!S13)) | D12: =IF($B12="","",IF('Pós-graduação'!G13="","",'Pós-graduação'!G13)) | E12: =IF($B12="","",IF('Pós-graduação'!H13<>"",'Pós-graduação'!H13,IF('Pós-graduação'!I13<>"",'Pós-graduação'!I13,""))) | F12: =IF($B12="","",IF('Pós-graduação'!I13="","",'Pós-graduação'!I13)) | G12: =IF($B12="","",'Pós-graduação'!N13) | H12: =IF(OR($B12="",$F12=""),"",IF(AND($F12>=H$7,$F12<EDATE(H$7,1)),"▼","")) | I12: =IF(OR($B12="",$F12=""),"",IF(AND($F12>=I$7,$F12<EDATE(I$7,1)),"▼","")) | J12: =IF(OR($B12="",$F12=""),"",IF(AND($F12>=J$7,$F12<EDATE(J$7,1)),"▼","")) | K12: =IF(OR($B12="",$F12=""),"",IF(AND($F12>=K$7,$F12<EDATE(K$7,1)),"▼","")) | L12: =IF(OR($B12="",$F12=""),"",IF(AND($F12>=L$7,$F12<EDATE(L$7,1)),"▼","")) | M12: =IF(OR($B12="",$F12=""),"",IF(AND($F12>=M$7,$F12<EDATE(M$7,1)),"▼","")) | N12: =IF(OR($B12="",$F12=""),"",IF(AND($F12>=N$7,$F12<EDATE(N$7,1)),"▼","")) | O12: =IF(OR($B12="",$F12=""),"",IF(AND($F12>=O$7,$F12<EDATE(O$7,1)),"▼","")) | ... S12: =IF(OR($B12="",$F12=""),"",IF(AND($F12>=S$7,$F12<EDATE(S$7,1)),"▼",""))
A13: =IF($B13="","","Pós-graduação") | B13: =IF('Pós-graduação'!B14="","",'Pós-graduação'!B14) | C13: =IF($B13="","",IF('Pós-graduação'!S14="","",'Pós-graduação'!S14)) | D13: =IF($B13="","",IF('Pós-graduação'!G14="","",'Pós-graduação'!G14)) | E13: =IF($B13="","",IF('Pós-graduação'!H14<>"",'Pós-graduação'!H14,IF('Pós-graduação'!I14<>"",'Pós-graduação'!I14,""))) | F13: =IF($B13="","",IF('Pós-graduação'!I14="","",'Pós-graduação'!I14)) | G13: =IF($B13="","",'Pós-graduação'!N14) | H13: =IF(OR($B13="",$F13=""),"",IF(AND($F13>=H$7,$F13<EDATE(H$7,1)),"▼","")) | I13: =IF(OR($B13="",$F13=""),"",IF(AND($F13>=I$7,$F13<EDATE(I$7,1)),"▼","")) | J13: =IF(OR($B13="",$F13=""),"",IF(AND($F13>=J$7,$F13<EDATE(J$7,1)),"▼","")) | K13: =IF(OR($B13="",$F13=""),"",IF(AND($F13>=K$7,$F13<EDATE(K$7,1)),"▼","")) | L13: =IF(OR($B13="",$F13=""),"",IF(AND($F13>=L$7,$F13<EDATE(L$7,1)),"▼","")) | M13: =IF(OR($B13="",$F13=""),"",IF(AND($F13>=M$7,$F13<EDATE(M$7,1)),"▼","")) | N13: =IF(OR($B13="",$F13=""),"",IF(AND($F13>=N$7,$F13<EDATE(N$7,1)),"▼","")) | O13: =IF(OR($B13="",$F13=""),"",IF(AND($F13>=O$7,$F13<EDATE(O$7,1)),"▼","")) | ... S13: =IF(OR($B13="",$F13=""),"",IF(AND($F13>=S$7,$F13<EDATE(S$7,1)),"▼",""))
A14: =IF($B14="","","Pós-graduação") | B14: =IF('Pós-graduação'!B15="","",'Pós-graduação'!B15) | C14: =IF($B14="","",IF('Pós-graduação'!S15="","",'Pós-graduação'!S15)) | D14: =IF($B14="","",IF('Pós-graduação'!G15="","",'Pós-graduação'!G15)) | E14: =IF($B14="","",IF('Pós-graduação'!H15<>"",'Pós-graduação'!H15,IF('Pós-graduação'!I15<>"",'Pós-graduação'!I15,""))) | F14: =IF($B14="","",IF('Pós-graduação'!I15="","",'Pós-graduação'!I15)) | G14: =IF($B14="","",'Pós-graduação'!N15) | H14: =IF(OR($B14="",$F14=""),"",IF(AND($F14>=H$7,$F14<EDATE(H$7,1)),"▼","")) | I14: =IF(OR($B14="",$F14=""),"",IF(AND($F14>=I$7,$F14<EDATE(I$7,1)),"▼","")) | J14: =IF(OR($B14="",$F14=""),"",IF(AND($F14>=J$7,$F14<EDATE(J$7,1)),"▼","")) | K14: =IF(OR($B14="",$F14=""),"",IF(AND($F14>=K$7,$F14<EDATE(K$7,1)),"▼","")) | L14: =IF(OR($B14="",$F14=""),"",IF(AND($F14>=L$7,$F14<EDATE(L$7,1)),"▼","")) | M14: =IF(OR($B14="",$F14=""),"",IF(AND($F14>=M$7,$F14<EDATE(M$7,1)),"▼","")) | N14: =IF(OR($B14="",$F14=""),"",IF(AND($F14>=N$7,$F14<EDATE(N$7,1)),"▼","")) | O14: =IF(OR($B14="",$F14=""),"",IF(AND($F14>=O$7,$F14<EDATE(O$7,1)),"▼","")) | ... S14: =IF(OR($B14="",$F14=""),"",IF(AND($F14>=S$7,$F14<EDATE(S$7,1)),"▼",""))
A15: =IF($B15="","","Pós-graduação") | B15: =IF('Pós-graduação'!B16="","",'Pós-graduação'!B16) | C15: =IF($B15="","",IF('Pós-graduação'!S16="","",'Pós-graduação'!S16)) | D15: =IF($B15="","",IF('Pós-graduação'!G16="","",'Pós-graduação'!G16)) | E15: =IF($B15="","",IF('Pós-graduação'!H16<>"",'Pós-graduação'!H16,IF('Pós-graduação'!I16<>"",'Pós-graduação'!I16,""))) | F15: =IF($B15="","",IF('Pós-graduação'!I16="","",'Pós-graduação'!I16)) | G15: =IF($B15="","",'Pós-graduação'!N16) | H15: =IF(OR($B15="",$F15=""),"",IF(AND($F15>=H$7,$F15<EDATE(H$7,1)),"▼","")) | I15: =IF(OR($B15="",$F15=""),"",IF(AND($F15>=I$7,$F15<EDATE(I$7,1)),"▼","")) | J15: =IF(OR($B15="",$F15=""),"",IF(AND($F15>=J$7,$F15<EDATE(J$7,1)),"▼","")) | K15: =IF(OR($B15="",$F15=""),"",IF(AND($F15>=K$7,$F15<EDATE(K$7,1)),"▼","")) | L15: =IF(OR($B15="",$F15=""),"",IF(AND($F15>=L$7,$F15<EDATE(L$7,1)),"▼","")) | M15: =IF(OR($B15="",$F15=""),"",IF(AND($F15>=M$7,$F15<EDATE(M$7,1)),"▼","")) | N15: =IF(OR($B15="",$F15=""),"",IF(AND($F15>=N$7,$F15<EDATE(N$7,1)),"▼","")) | O15: =IF(OR($B15="",$F15=""),"",IF(AND($F15>=O$7,$F15<EDATE(O$7,1)),"▼","")) | ... S15: =IF(OR($B15="",$F15=""),"",IF(AND($F15>=S$7,$F15<EDATE(S$7,1)),"▼",""))
A16: =IF($B16="","","Pós-graduação") | B16: =IF('Pós-graduação'!B17="","",'Pós-graduação'!B17) | C16: =IF($B16="","",IF('Pós-graduação'!S17="","",'Pós-graduação'!S17)) | D16: =IF($B16="","",IF('Pós-graduação'!G17="","",'Pós-graduação'!G17)) | E16: =IF($B16="","",IF('Pós-graduação'!H17<>"",'Pós-graduação'!H17,IF('Pós-graduação'!I17<>"",'Pós-graduação'!I17,""))) | F16: =IF($B16="","",IF('Pós-graduação'!I17="","",'Pós-graduação'!I17)) | G16: =IF($B16="","",'Pós-graduação'!N17) | H16: =IF(OR($B16="",$F16=""),"",IF(AND($F16>=H$7,$F16<EDATE(H$7,1)),"▼","")) | I16: =IF(OR($B16="",$F16=""),"",IF(AND($F16>=I$7,$F16<EDATE(I$7,1)),"▼","")) | J16: =IF(OR($B16="",$F16=""),"",IF(AND($F16>=J$7,$F16<EDATE(J$7,1)),"▼","")) | K16: =IF(OR($B16="",$F16=""),"",IF(AND($F16>=K$7,$F16<EDATE(K$7,1)),"▼","")) | L16: =IF(OR($B16="",$F16=""),"",IF(AND($F16>=L$7,$F16<EDATE(L$7,1)),"▼","")) | M16: =IF(OR($B16="",$F16=""),"",IF(AND($F16>=M$7,$F16<EDATE(M$7,1)),"▼","")) | N16: =IF(OR($B16="",$F16=""),"",IF(AND($F16>=N$7,$F16<EDATE(N$7,1)),"▼","")) | O16: =IF(OR($B16="",$F16=""),"",IF(AND($F16>=O$7,$F16<EDATE(O$7,1)),"▼","")) | ... S16: =IF(OR($B16="",$F16=""),"",IF(AND($F16>=S$7,$F16<EDATE(S$7,1)),"▼",""))
A17: =IF($B17="","","Pós-graduação") | B17: =IF('Pós-graduação'!B18="","",'Pós-graduação'!B18) | C17: =IF($B17="","",IF('Pós-graduação'!S18="","",'Pós-graduação'!S18)) | D17: =IF($B17="","",IF('Pós-graduação'!G18="","",'Pós-graduação'!G18)) | E17: =IF($B17="","",IF('Pós-graduação'!H18<>"",'Pós-graduação'!H18,IF('Pós-graduação'!I18<>"",'Pós-graduação'!I18,""))) | F17: =IF($B17="","",IF('Pós-graduação'!I18="","",'Pós-graduação'!I18)) | G17: =IF($B17="","",'Pós-graduação'!N18) | H17: =IF(OR($B17="",$F17=""),"",IF(AND($F17>=H$7,$F17<EDATE(H$7,1)),"▼","")) | I17: =IF(OR($B17="",$F17=""),"",IF(AND($F17>=I$7,$F17<EDATE(I$7,1)),"▼","")) | J17: =IF(OR($B17="",$F17=""),"",IF(AND($F17>=J$7,$F17<EDATE(J$7,1)),"▼","")) | K17: =IF(OR($B17="",$F17=""),"",IF(AND($F17>=K$7,$F17<EDATE(K$7,1)),"▼","")) | L17: =IF(OR($B17="",$F17=""),"",IF(AND($F17>=L$7,$F17<EDATE(L$7,1)),"▼","")) | M17: =IF(OR($B17="",$F17=""),"",IF(AND($F17>=M$7,$F17<EDATE(M$7,1)),"▼","")) | N17: =IF(OR($B17="",$F17=""),"",IF(AND($F17>=N$7,$F17<EDATE(N$7,1)),"▼","")) | O17: =IF(OR($B17="",$F17=""),"",IF(AND($F17>=O$7,$F17<EDATE(O$7,1)),"▼","")) | ... S17: =IF(OR($B17="",$F17=""),"",IF(AND($F17>=S$7,$F17<EDATE(S$7,1)),"▼",""))
A18: =IF($B18="","","Pós-graduação") | B18: =IF('Pós-graduação'!B19="","",'Pós-graduação'!B19) | C18: =IF($B18="","",IF('Pós-graduação'!S19="","",'Pós-graduação'!S19)) | D18: =IF($B18="","",IF('Pós-graduação'!G19="","",'Pós-graduação'!G19)) | E18: =IF($B18="","",IF('Pós-graduação'!H19<>"",'Pós-graduação'!H19,IF('Pós-graduação'!I19<>"",'Pós-graduação'!I19,""))) | F18: =IF($B18="","",IF('Pós-graduação'!I19="","",'Pós-graduação'!I19)) | G18: =IF($B18="","",'Pós-graduação'!N19) | H18: =IF(OR($B18="",$F18=""),"",IF(AND($F18>=H$7,$F18<EDATE(H$7,1)),"▼","")) | I18: =IF(OR($B18="",$F18=""),"",IF(AND($F18>=I$7,$F18<EDATE(I$7,1)),"▼","")) | J18: =IF(OR($B18="",$F18=""),"",IF(AND($F18>=J$7,$F18<EDATE(J$7,1)),"▼","")) | K18: =IF(OR($B18="",$F18=""),"",IF(AND($F18>=K$7,$F18<EDATE(K$7,1)),"▼","")) | L18: =IF(OR($B18="",$F18=""),"",IF(AND($F18>=L$7,$F18<EDATE(L$7,1)),"▼","")) | M18: =IF(OR($B18="",$F18=""),"",IF(AND($F18>=M$7,$F18<EDATE(M$7,1)),"▼","")) | N18: =IF(OR($B18="",$F18=""),"",IF(AND($F18>=N$7,$F18<EDATE(N$7,1)),"▼","")) | O18: =IF(OR($B18="",$F18=""),"",IF(AND($F18>=O$7,$F18<EDATE(O$7,1)),"▼","")) | ... S18: =IF(OR($B18="",$F18=""),"",IF(AND($F18>=S$7,$F18<EDATE(S$7,1)),"▼",""))
A19: =IF($B19="","","Pós-graduação") | B19: =IF('Pós-graduação'!B20="","",'Pós-graduação'!B20) | C19: =IF($B19="","",IF('Pós-graduação'!S20="","",'Pós-graduação'!S20)) | D19: =IF($B19="","",IF('Pós-graduação'!G20="","",'Pós-graduação'!G20)) | E19: =IF($B19="","",IF('Pós-graduação'!H20<>"",'Pós-graduação'!H20,IF('Pós-graduação'!I20<>"",'Pós-graduação'!I20,""))) | F19: =IF($B19="","",IF('Pós-graduação'!I20="","",'Pós-graduação'!I20)) | G19: =IF($B19="","",'Pós-graduação'!N20) | H19: =IF(OR($B19="",$F19=""),"",IF(AND($F19>=H$7,$F19<EDATE(H$7,1)),"▼","")) | I19: =IF(OR($B19="",$F19=""),"",IF(AND($F19>=I$7,$F19<EDATE(I$7,1)),"▼","")) | J19: =IF(OR($B19="",$F19=""),"",IF(AND($F19>=J$7,$F19<EDATE(J$7,1)),"▼","")) | K19: =IF(OR($B19="",$F19=""),"",IF(AND($F19>=K$7,$F19<EDATE(K$7,1)),"▼","")) | L19: =IF(OR($B19="",$F19=""),"",IF(AND($F19>=L$7,$F19<EDATE(L$7,1)),"▼","")) | M19: =IF(OR($B19="",$F19=""),"",IF(AND($F19>=M$7,$F19<EDATE(M$7,1)),"▼","")) | N19: =IF(OR($B19="",$F19=""),"",IF(AND($F19>=N$7,$F19<EDATE(N$7,1)),"▼","")) | O19: =IF(OR($B19="",$F19=""),"",IF(AND($F19>=O$7,$F19<EDATE(O$7,1)),"▼","")) | ... S19: =IF(OR($B19="",$F19=""),"",IF(AND($F19>=S$7,$F19<EDATE(S$7,1)),"▼",""))
A20: =IF($B20="","","Pós-graduação") | B20: =IF('Pós-graduação'!B21="","",'Pós-graduação'!B21) | C20: =IF($B20="","",IF('Pós-graduação'!S21="","",'Pós-graduação'!S21)) | D20: =IF($B20="","",IF('Pós-graduação'!G21="","",'Pós-graduação'!G21)) | E20: =IF($B20="","",IF('Pós-graduação'!H21<>"",'Pós-graduação'!H21,IF('Pós-graduação'!I21<>"",'Pós-graduação'!I21,""))) | F20: =IF($B20="","",IF('Pós-graduação'!I21="","",'Pós-graduação'!I21)) | G20: =IF($B20="","",'Pós-graduação'!N21) | H20: =IF(OR($B20="",$F20=""),"",IF(AND($F20>=H$7,$F20<EDATE(H$7,1)),"▼","")) | I20: =IF(OR($B20="",$F20=""),"",IF(AND($F20>=I$7,$F20<EDATE(I$7,1)),"▼","")) | J20: =IF(OR($B20="",$F20=""),"",IF(AND($F20>=J$7,$F20<EDATE(J$7,1)),"▼","")) | K20: =IF(OR($B20="",$F20=""),"",IF(AND($F20>=K$7,$F20<EDATE(K$7,1)),"▼","")) | L20: =IF(OR($B20="",$F20=""),"",IF(AND($F20>=L$7,$F20<EDATE(L$7,1)),"▼","")) | M20: =IF(OR($B20="",$F20=""),"",IF(AND($F20>=M$7,$F20<EDATE(M$7,1)),"▼","")) | N20: =IF(OR($B20="",$F20=""),"",IF(AND($F20>=N$7,$F20<EDATE(N$7,1)),"▼","")) | O20: =IF(OR($B20="",$F20=""),"",IF(AND($F20>=O$7,$F20<EDATE(O$7,1)),"▼","")) | ... S20: =IF(OR($B20="",$F20=""),"",IF(AND($F20>=S$7,$F20<EDATE(S$7,1)),"▼",""))
A21: CONCURSO
A22: =IF($B22="","","Concurso") -> Concurso | B22: =IF(Concurso!B10="","",Concurso!B10) -> Curso Preparatório Completo (exemplo) | C22: =IF($B22="","",IF(Concurso!U10="","",Concurso!U10)) -> Em andamento | D22: =IF($B22="","",IF(Concurso!I10="","",Concurso!I10)) -> 46280 | E22: =IF($B22="","",IF(Concurso!J10<>"",Concurso!J10,IF(Concurso!K10<>"",Concurso!K10,""))) -> 46446 | F22: =IF($B22="","",IF(Concurso!K10="","",Concurso!K10)) -> 46568 | G22: =IF($B22="","",Concurso!P10) -> 0.25 | H22: =IF(OR($B22="",$F22=""),"",IF(AND($F22>=H$7,$F22<EDATE(H$7,1)),"▼","")) | I22: =IF(OR($B22="",$F22=""),"",IF(AND($F22>=I$7,$F22<EDATE(I$7,1)),"▼","")) | J22: =IF(OR($B22="",$F22=""),"",IF(AND($F22>=J$7,$F22<EDATE(J$7,1)),"▼","")) | K22: =IF(OR($B22="",$F22=""),"",IF(AND($F22>=K$7,$F22<EDATE(K$7,1)),"▼","")) | L22: =IF(OR($B22="",$F22=""),"",IF(AND($F22>=L$7,$F22<EDATE(L$7,1)),"▼","")) | M22: =IF(OR($B22="",$F22=""),"",IF(AND($F22>=M$7,$F22<EDATE(M$7,1)),"▼","")) | N22: =IF(OR($B22="",$F22=""),"",IF(AND($F22>=N$7,$F22<EDATE(N$7,1)),"▼","")) | O22: =IF(OR($B22="",$F22=""),"",IF(AND($F22>=O$7,$F22<EDATE(O$7,1)),"▼","")) | ... S22: =IF(OR($B22="",$F22=""),"",IF(AND($F22>=S$7,$F22<EDATE(S$7,1)),"▼",""))
A23: =IF($B23="","","Concurso") | B23: =IF(Concurso!B11="","",Concurso!B11) | C23: =IF($B23="","",IF(Concurso!U11="","",Concurso!U11)) | D23: =IF($B23="","",IF(Concurso!I11="","",Concurso!I11)) | E23: =IF($B23="","",IF(Concurso!J11<>"",Concurso!J11,IF(Concurso!K11<>"",Concurso!K11,""))) | F23: =IF($B23="","",IF(Concurso!K11="","",Concurso!K11)) | G23: =IF($B23="","",Concurso!P11) | H23: =IF(OR($B23="",$F23=""),"",IF(AND($F23>=H$7,$F23<EDATE(H$7,1)),"▼","")) | I23: =IF(OR($B23="",$F23=""),"",IF(AND($F23>=I$7,$F23<EDATE(I$7,1)),"▼","")) | J23: =IF(OR($B23="",$F23=""),"",IF(AND($F23>=J$7,$F23<EDATE(J$7,1)),"▼","")) | K23: =IF(OR($B23="",$F23=""),"",IF(AND($F23>=K$7,$F23<EDATE(K$7,1)),"▼","")) | L23: =IF(OR($B23="",$F23=""),"",IF(AND($F23>=L$7,$F23<EDATE(L$7,1)),"▼","")) | M23: =IF(OR($B23="",$F23=""),"",IF(AND($F23>=M$7,$F23<EDATE(M$7,1)),"▼","")) | N23: =IF(OR($B23="",$F23=""),"",IF(AND($F23>=N$7,$F23<EDATE(N$7,1)),"▼","")) | O23: =IF(OR($B23="",$F23=""),"",IF(AND($F23>=O$7,$F23<EDATE(O$7,1)),"▼","")) | ... S23: =IF(OR($B23="",$F23=""),"",IF(AND($F23>=S$7,$F23<EDATE(S$7,1)),"▼",""))
A24: =IF($B24="","","Concurso") | B24: =IF(Concurso!B12="","",Concurso!B12) | C24: =IF($B24="","",IF(Concurso!U12="","",Concurso!U12)) | D24: =IF($B24="","",IF(Concurso!I12="","",Concurso!I12)) | E24: =IF($B24="","",IF(Concurso!J12<>"",Concurso!J12,IF(Concurso!K12<>"",Concurso!K12,""))) | F24: =IF($B24="","",IF(Concurso!K12="","",Concurso!K12)) | G24: =IF($B24="","",Concurso!P12) | H24: =IF(OR($B24="",$F24=""),"",IF(AND($F24>=H$7,$F24<EDATE(H$7,1)),"▼","")) | I24: =IF(OR($B24="",$F24=""),"",IF(AND($F24>=I$7,$F24<EDATE(I$7,1)),"▼","")) | J24: =IF(OR($B24="",$F24=""),"",IF(AND($F24>=J$7,$F24<EDATE(J$7,1)),"▼","")) | K24: =IF(OR($B24="",$F24=""),"",IF(AND($F24>=K$7,$F24<EDATE(K$7,1)),"▼","")) | L24: =IF(OR($B24="",$F24=""),"",IF(AND($F24>=L$7,$F24<EDATE(L$7,1)),"▼","")) | M24: =IF(OR($B24="",$F24=""),"",IF(AND($F24>=M$7,$F24<EDATE(M$7,1)),"▼","")) | N24: =IF(OR($B24="",$F24=""),"",IF(AND($F24>=N$7,$F24<EDATE(N$7,1)),"▼","")) | O24: =IF(OR($B24="",$F24=""),"",IF(AND($F24>=O$7,$F24<EDATE(O$7,1)),"▼","")) | ... S24: =IF(OR($B24="",$F24=""),"",IF(AND($F24>=S$7,$F24<EDATE(S$7,1)),"▼",""))
A25: =IF($B25="","","Concurso") | B25: =IF(Concurso!B13="","",Concurso!B13) | C25: =IF($B25="","",IF(Concurso!U13="","",Concurso!U13)) | D25: =IF($B25="","",IF(Concurso!I13="","",Concurso!I13)) | E25: =IF($B25="","",IF(Concurso!J13<>"",Concurso!J13,IF(Concurso!K13<>"",Concurso!K13,""))) | F25: =IF($B25="","",IF(Concurso!K13="","",Concurso!K13)) | G25: =IF($B25="","",Concurso!P13) | H25: =IF(OR($B25="",$F25=""),"",IF(AND($F25>=H$7,$F25<EDATE(H$7,1)),"▼","")) | I25: =IF(OR($B25="",$F25=""),"",IF(AND($F25>=I$7,$F25<EDATE(I$7,1)),"▼","")) | J25: =IF(OR($B25="",$F25=""),"",IF(AND($F25>=J$7,$F25<EDATE(J$7,1)),"▼","")) | K25: =IF(OR($B25="",$F25=""),"",IF(AND($F25>=K$7,$F25<EDATE(K$7,1)),"▼","")) | L25: =IF(OR($B25="",$F25=""),"",IF(AND($F25>=L$7,$F25<EDATE(L$7,1)),"▼","")) | M25: =IF(OR($B25="",$F25=""),"",IF(AND($F25>=M$7,$F25<EDATE(M$7,1)),"▼","")) | N25: =IF(OR($B25="",$F25=""),"",IF(AND($F25>=N$7,$F25<EDATE(N$7,1)),"▼","")) | O25: =IF(OR($B25="",$F25=""),"",IF(AND($F25>=O$7,$F25<EDATE(O$7,1)),"▼","")) | ... S25: =IF(OR($B25="",$F25=""),"",IF(AND($F25>=S$7,$F25<EDATE(S$7,1)),"▼",""))
A26: =IF($B26="","","Concurso") | B26: =IF(Concurso!B14="","",Concurso!B14) | C26: =IF($B26="","",IF(Concurso!U14="","",Concurso!U14)) | D26: =IF($B26="","",IF(Concurso!I14="","",Concurso!I14)) | E26: =IF($B26="","",IF(Concurso!J14<>"",Concurso!J14,IF(Concurso!K14<>"",Concurso!K14,""))) | F26: =IF($B26="","",IF(Concurso!K14="","",Concurso!K14)) | G26: =IF($B26="","",Concurso!P14) | H26: =IF(OR($B26="",$F26=""),"",IF(AND($F26>=H$7,$F26<EDATE(H$7,1)),"▼","")) | I26: =IF(OR($B26="",$F26=""),"",IF(AND($F26>=I$7,$F26<EDATE(I$7,1)),"▼","")) | J26: =IF(OR($B26="",$F26=""),"",IF(AND($F26>=J$7,$F26<EDATE(J$7,1)),"▼","")) | K26: =IF(OR($B26="",$F26=""),"",IF(AND($F26>=K$7,$F26<EDATE(K$7,1)),"▼","")) | L26: =IF(OR($B26="",$F26=""),"",IF(AND($F26>=L$7,$F26<EDATE(L$7,1)),"▼","")) | M26: =IF(OR($B26="",$F26=""),"",IF(AND($F26>=M$7,$F26<EDATE(M$7,1)),"▼","")) | N26: =IF(OR($B26="",$F26=""),"",IF(AND($F26>=N$7,$F26<EDATE(N$7,1)),"▼","")) | O26: =IF(OR($B26="",$F26=""),"",IF(AND($F26>=O$7,$F26<EDATE(O$7,1)),"▼","")) | ... S26: =IF(OR($B26="",$F26=""),"",IF(AND($F26>=S$7,$F26<EDATE(S$7,1)),"▼",""))
A27: =IF($B27="","","Concurso") | B27: =IF(Concurso!B15="","",Concurso!B15) | C27: =IF($B27="","",IF(Concurso!U15="","",Concurso!U15)) | D27: =IF($B27="","",IF(Concurso!I15="","",Concurso!I15)) | E27: =IF($B27="","",IF(Concurso!J15<>"",Concurso!J15,IF(Concurso!K15<>"",Concurso!K15,""))) | F27: =IF($B27="","",IF(Concurso!K15="","",Concurso!K15)) | G27: =IF($B27="","",Concurso!P15) | H27: =IF(OR($B27="",$F27=""),"",IF(AND($F27>=H$7,$F27<EDATE(H$7,1)),"▼","")) | I27: =IF(OR($B27="",$F27=""),"",IF(AND($F27>=I$7,$F27<EDATE(I$7,1)),"▼","")) | J27: =IF(OR($B27="",$F27=""),"",IF(AND($F27>=J$7,$F27<EDATE(J$7,1)),"▼","")) | K27: =IF(OR($B27="",$F27=""),"",IF(AND($F27>=K$7,$F27<EDATE(K$7,1)),"▼","")) | L27: =IF(OR($B27="",$F27=""),"",IF(AND($F27>=L$7,$F27<EDATE(L$7,1)),"▼","")) | M27: =IF(OR($B27="",$F27=""),"",IF(AND($F27>=M$7,$F27<EDATE(M$7,1)),"▼","")) | N27: =IF(OR($B27="",$F27=""),"",IF(AND($F27>=N$7,$F27<EDATE(N$7,1)),"▼","")) | O27: =IF(OR($B27="",$F27=""),"",IF(AND($F27>=O$7,$F27<EDATE(O$7,1)),"▼","")) | ... S27: =IF(OR($B27="",$F27=""),"",IF(AND($F27>=S$7,$F27<EDATE(S$7,1)),"▼",""))
A28: =IF($B28="","","Concurso") | B28: =IF(Concurso!B16="","",Concurso!B16) | C28: =IF($B28="","",IF(Concurso!U16="","",Concurso!U16)) | D28: =IF($B28="","",IF(Concurso!I16="","",Concurso!I16)) | E28: =IF($B28="","",IF(Concurso!J16<>"",Concurso!J16,IF(Concurso!K16<>"",Concurso!K16,""))) | F28: =IF($B28="","",IF(Concurso!K16="","",Concurso!K16)) | G28: =IF($B28="","",Concurso!P16) | H28: =IF(OR($B28="",$F28=""),"",IF(AND($F28>=H$7,$F28<EDATE(H$7,1)),"▼","")) | I28: =IF(OR($B28="",$F28=""),"",IF(AND($F28>=I$7,$F28<EDATE(I$7,1)),"▼","")) | J28: =IF(OR($B28="",$F28=""),"",IF(AND($F28>=J$7,$F28<EDATE(J$7,1)),"▼","")) | K28: =IF(OR($B28="",$F28=""),"",IF(AND($F28>=K$7,$F28<EDATE(K$7,1)),"▼","")) | L28: =IF(OR($B28="",$F28=""),"",IF(AND($F28>=L$7,$F28<EDATE(L$7,1)),"▼","")) | M28: =IF(OR($B28="",$F28=""),"",IF(AND($F28>=M$7,$F28<EDATE(M$7,1)),"▼","")) | N28: =IF(OR($B28="",$F28=""),"",IF(AND($F28>=N$7,$F28<EDATE(N$7,1)),"▼","")) | O28: =IF(OR($B28="",$F28=""),"",IF(AND($F28>=O$7,$F28<EDATE(O$7,1)),"▼","")) | ... S28: =IF(OR($B28="",$F28=""),"",IF(AND($F28>=S$7,$F28<EDATE(S$7,1)),"▼",""))
A29: =IF($B29="","","Concurso") | B29: =IF(Concurso!B17="","",Concurso!B17) | C29: =IF($B29="","",IF(Concurso!U17="","",Concurso!U17)) | D29: =IF($B29="","",IF(Concurso!I17="","",Concurso!I17)) | E29: =IF($B29="","",IF(Concurso!J17<>"",Concurso!J17,IF(Concurso!K17<>"",Concurso!K17,""))) | F29: =IF($B29="","",IF(Concurso!K17="","",Concurso!K17)) | G29: =IF($B29="","",Concurso!P17) | H29: =IF(OR($B29="",$F29=""),"",IF(AND($F29>=H$7,$F29<EDATE(H$7,1)),"▼","")) | I29: =IF(OR($B29="",$F29=""),"",IF(AND($F29>=I$7,$F29<EDATE(I$7,1)),"▼","")) | J29: =IF(OR($B29="",$F29=""),"",IF(AND($F29>=J$7,$F29<EDATE(J$7,1)),"▼","")) | K29: =IF(OR($B29="",$F29=""),"",IF(AND($F29>=K$7,$F29<EDATE(K$7,1)),"▼","")) | L29: =IF(OR($B29="",$F29=""),"",IF(AND($F29>=L$7,$F29<EDATE(L$7,1)),"▼","")) | M29: =IF(OR($B29="",$F29=""),"",IF(AND($F29>=M$7,$F29<EDATE(M$7,1)),"▼","")) | N29: =IF(OR($B29="",$F29=""),"",IF(AND($F29>=N$7,$F29<EDATE(N$7,1)),"▼","")) | O29: =IF(OR($B29="",$F29=""),"",IF(AND($F29>=O$7,$F29<EDATE(O$7,1)),"▼","")) | ... S29: =IF(OR($B29="",$F29=""),"",IF(AND($F29>=S$7,$F29<EDATE(S$7,1)),"▼",""))
A30: =IF($B30="","","Concurso") | B30: =IF(Concurso!B18="","",Concurso!B18) | C30: =IF($B30="","",IF(Concurso!U18="","",Concurso!U18)) | D30: =IF($B30="","",IF(Concurso!I18="","",Concurso!I18)) | E30: =IF($B30="","",IF(Concurso!J18<>"",Concurso!J18,IF(Concurso!K18<>"",Concurso!K18,""))) | F30: =IF($B30="","",IF(Concurso!K18="","",Concurso!K18)) | G30: =IF($B30="","",Concurso!P18) | H30: =IF(OR($B30="",$F30=""),"",IF(AND($F30>=H$7,$F30<EDATE(H$7,1)),"▼","")) | I30: =IF(OR($B30="",$F30=""),"",IF(AND($F30>=I$7,$F30<EDATE(I$7,1)),"▼","")) | J30: =IF(OR($B30="",$F30=""),"",IF(AND($F30>=J$7,$F30<EDATE(J$7,1)),"▼","")) | K30: =IF(OR($B30="",$F30=""),"",IF(AND($F30>=K$7,$F30<EDATE(K$7,1)),"▼","")) | L30: =IF(OR($B30="",$F30=""),"",IF(AND($F30>=L$7,$F30<EDATE(L$7,1)),"▼","")) | M30: =IF(OR($B30="",$F30=""),"",IF(AND($F30>=M$7,$F30<EDATE(M$7,1)),"▼","")) | N30: =IF(OR($B30="",$F30=""),"",IF(AND($F30>=N$7,$F30<EDATE(N$7,1)),"▼","")) | O30: =IF(OR($B30="",$F30=""),"",IF(AND($F30>=O$7,$F30<EDATE(O$7,1)),"▼","")) | ... S30: =IF(OR($B30="",$F30=""),"",IF(AND($F30>=S$7,$F30<EDATE(S$7,1)),"▼",""))
A31: =IF($B31="","","Concurso") | B31: =IF(Concurso!B19="","",Concurso!B19) | C31: =IF($B31="","",IF(Concurso!U19="","",Concurso!U19)) | D31: =IF($B31="","",IF(Concurso!I19="","",Concurso!I19)) | E31: =IF($B31="","",IF(Concurso!J19<>"",Concurso!J19,IF(Concurso!K19<>"",Concurso!K19,""))) | F31: =IF($B31="","",IF(Concurso!K19="","",Concurso!K19)) | G31: =IF($B31="","",Concurso!P19) | H31: =IF(OR($B31="",$F31=""),"",IF(AND($F31>=H$7,$F31<EDATE(H$7,1)),"▼","")) | I31: =IF(OR($B31="",$F31=""),"",IF(AND($F31>=I$7,$F31<EDATE(I$7,1)),"▼","")) | J31: =IF(OR($B31="",$F31=""),"",IF(AND($F31>=J$7,$F31<EDATE(J$7,1)),"▼","")) | K31: =IF(OR($B31="",$F31=""),"",IF(AND($F31>=K$7,$F31<EDATE(K$7,1)),"▼","")) | L31: =IF(OR($B31="",$F31=""),"",IF(AND($F31>=L$7,$F31<EDATE(L$7,1)),"▼","")) | M31: =IF(OR($B31="",$F31=""),"",IF(AND($F31>=M$7,$F31<EDATE(M$7,1)),"▼","")) | N31: =IF(OR($B31="",$F31=""),"",IF(AND($F31>=N$7,$F31<EDATE(N$7,1)),"▼","")) | O31: =IF(OR($B31="",$F31=""),"",IF(AND($F31>=O$7,$F31<EDATE(O$7,1)),"▼","")) | ... S31: =IF(OR($B31="",$F31=""),"",IF(AND($F31>=S$7,$F31<EDATE(S$7,1)),"▼",""))
A32: =IF($B32="","","Concurso") | B32: =IF(Concurso!B20="","",Concurso!B20) | C32: =IF($B32="","",IF(Concurso!U20="","",Concurso!U20)) | D32: =IF($B32="","",IF(Concurso!I20="","",Concurso!I20)) | E32: =IF($B32="","",IF(Concurso!J20<>"",Concurso!J20,IF(Concurso!K20<>"",Concurso!K20,""))) | F32: =IF($B32="","",IF(Concurso!K20="","",Concurso!K20)) | G32: =IF($B32="","",Concurso!P20) | H32: =IF(OR($B32="",$F32=""),"",IF(AND($F32>=H$7,$F32<EDATE(H$7,1)),"▼","")) | I32: =IF(OR($B32="",$F32=""),"",IF(AND($F32>=I$7,$F32<EDATE(I$7,1)),"▼","")) | J32: =IF(OR($B32="",$F32=""),"",IF(AND($F32>=J$7,$F32<EDATE(J$7,1)),"▼","")) | K32: =IF(OR($B32="",$F32=""),"",IF(AND($F32>=K$7,$F32<EDATE(K$7,1)),"▼","")) | L32: =IF(OR($B32="",$F32=""),"",IF(AND($F32>=L$7,$F32<EDATE(L$7,1)),"▼","")) | M32: =IF(OR($B32="",$F32=""),"",IF(AND($F32>=M$7,$F32<EDATE(M$7,1)),"▼","")) | N32: =IF(OR($B32="",$F32=""),"",IF(AND($F32>=N$7,$F32<EDATE(N$7,1)),"▼","")) | O32: =IF(OR($B32="",$F32=""),"",IF(AND($F32>=O$7,$F32<EDATE(O$7,1)),"▼","")) | ... S32: =IF(OR($B32="",$F32=""),"",IF(AND($F32>=S$7,$F32<EDATE(S$7,1)),"▼",""))
A33: =IF($B33="","","Concurso") | B33: =IF(Concurso!B21="","",Concurso!B21) | C33: =IF($B33="","",IF(Concurso!U21="","",Concurso!U21)) | D33: =IF($B33="","",IF(Concurso!I21="","",Concurso!I21)) | E33: =IF($B33="","",IF(Concurso!J21<>"",Concurso!J21,IF(Concurso!K21<>"",Concurso!K21,""))) | F33: =IF($B33="","",IF(Concurso!K21="","",Concurso!K21)) | G33: =IF($B33="","",Concurso!P21) | H33: =IF(OR($B33="",$F33=""),"",IF(AND($F33>=H$7,$F33<EDATE(H$7,1)),"▼","")) | I33: =IF(OR($B33="",$F33=""),"",IF(AND($F33>=I$7,$F33<EDATE(I$7,1)),"▼","")) | J33: =IF(OR($B33="",$F33=""),"",IF(AND($F33>=J$7,$F33<EDATE(J$7,1)),"▼","")) | K33: =IF(OR($B33="",$F33=""),"",IF(AND($F33>=K$7,$F33<EDATE(K$7,1)),"▼","")) | L33: =IF(OR($B33="",$F33=""),"",IF(AND($F33>=L$7,$F33<EDATE(L$7,1)),"▼","")) | M33: =IF(OR($B33="",$F33=""),"",IF(AND($F33>=M$7,$F33<EDATE(M$7,1)),"▼","")) | N33: =IF(OR($B33="",$F33=""),"",IF(AND($F33>=N$7,$F33<EDATE(N$7,1)),"▼","")) | O33: =IF(OR($B33="",$F33=""),"",IF(AND($F33>=O$7,$F33<EDATE(O$7,1)),"▼","")) | ... S33: =IF(OR($B33="",$F33=""),"",IF(AND($F33>=S$7,$F33<EDATE(S$7,1)),"▼",""))
A34: LIVROS
A35: =IF($B35="","","Livros") -> Livros | B35: =IF(Livros!B10="","",Livros!B10) -> Hábitos Atômicos (exemplo) | C35: =IF($B35="","",IF(Livros!R10="","",Livros!R10)) -> Em andamento | D35: =IF($B35="","",IF(Livros!I10="","",Livros!I10)) -> 46290 | E35: =IF($B35="","",IF(Livros!J10="","",Livros!J10)) -> 46341 | F35: ="" | G35: =IF($B35="","",Livros!M10) -> 0.375 | H35: =IF(OR($B35="",$F35=""),"",IF(AND($F35>=H$7,$F35<EDATE(H$7,1)),"▼","")) | I35: =IF(OR($B35="",$F35=""),"",IF(AND($F35>=I$7,$F35<EDATE(I$7,1)),"▼","")) | J35: =IF(OR($B35="",$F35=""),"",IF(AND($F35>=J$7,$F35<EDATE(J$7,1)),"▼","")) | K35: =IF(OR($B35="",$F35=""),"",IF(AND($F35>=K$7,$F35<EDATE(K$7,1)),"▼","")) | L35: =IF(OR($B35="",$F35=""),"",IF(AND($F35>=L$7,$F35<EDATE(L$7,1)),"▼","")) | M35: =IF(OR($B35="",$F35=""),"",IF(AND($F35>=M$7,$F35<EDATE(M$7,1)),"▼","")) | N35: =IF(OR($B35="",$F35=""),"",IF(AND($F35>=N$7,$F35<EDATE(N$7,1)),"▼","")) | O35: =IF(OR($B35="",$F35=""),"",IF(AND($F35>=O$7,$F35<EDATE(O$7,1)),"▼","")) | ... S35: =IF(OR($B35="",$F35=""),"",IF(AND($F35>=S$7,$F35<EDATE(S$7,1)),"▼",""))
A36: =IF($B36="","","Livros") | B36: =IF(Livros!B11="","",Livros!B11) | C36: =IF($B36="","",IF(Livros!R11="","",Livros!R11)) | D36: =IF($B36="","",IF(Livros!I11="","",Livros!I11)) | E36: =IF($B36="","",IF(Livros!J11="","",Livros!J11)) | F36: ="" | G36: =IF($B36="","",Livros!M11) | H36: =IF(OR($B36="",$F36=""),"",IF(AND($F36>=H$7,$F36<EDATE(H$7,1)),"▼","")) | I36: =IF(OR($B36="",$F36=""),"",IF(AND($F36>=I$7,$F36<EDATE(I$7,1)),"▼","")) | J36: =IF(OR($B36="",$F36=""),"",IF(AND($F36>=J$7,$F36<EDATE(J$7,1)),"▼","")) | K36: =IF(OR($B36="",$F36=""),"",IF(AND($F36>=K$7,$F36<EDATE(K$7,1)),"▼","")) | L36: =IF(OR($B36="",$F36=""),"",IF(AND($F36>=L$7,$F36<EDATE(L$7,1)),"▼","")) | M36: =IF(OR($B36="",$F36=""),"",IF(AND($F36>=M$7,$F36<EDATE(M$7,1)),"▼","")) | N36: =IF(OR($B36="",$F36=""),"",IF(AND($F36>=N$7,$F36<EDATE(N$7,1)),"▼","")) | O36: =IF(OR($B36="",$F36=""),"",IF(AND($F36>=O$7,$F36<EDATE(O$7,1)),"▼","")) | ... S36: =IF(OR($B36="",$F36=""),"",IF(AND($F36>=S$7,$F36<EDATE(S$7,1)),"▼",""))
A37: =IF($B37="","","Livros") | B37: =IF(Livros!B12="","",Livros!B12) | C37: =IF($B37="","",IF(Livros!R12="","",Livros!R12)) | D37: =IF($B37="","",IF(Livros!I12="","",Livros!I12)) | E37: =IF($B37="","",IF(Livros!J12="","",Livros!J12)) | F37: ="" | G37: =IF($B37="","",Livros!M12) | H37: =IF(OR($B37="",$F37=""),"",IF(AND($F37>=H$7,$F37<EDATE(H$7,1)),"▼","")) | I37: =IF(OR($B37="",$F37=""),"",IF(AND($F37>=I$7,$F37<EDATE(I$7,1)),"▼","")) | J37: =IF(OR($B37="",$F37=""),"",IF(AND($F37>=J$7,$F37<EDATE(J$7,1)),"▼","")) | K37: =IF(OR($B37="",$F37=""),"",IF(AND($F37>=K$7,$F37<EDATE(K$7,1)),"▼","")) | L37: =IF(OR($B37="",$F37=""),"",IF(AND($F37>=L$7,$F37<EDATE(L$7,1)),"▼","")) | M37: =IF(OR($B37="",$F37=""),"",IF(AND($F37>=M$7,$F37<EDATE(M$7,1)),"▼","")) | N37: =IF(OR($B37="",$F37=""),"",IF(AND($F37>=N$7,$F37<EDATE(N$7,1)),"▼","")) | O37: =IF(OR($B37="",$F37=""),"",IF(AND($F37>=O$7,$F37<EDATE(O$7,1)),"▼","")) | ... S37: =IF(OR($B37="",$F37=""),"",IF(AND($F37>=S$7,$F37<EDATE(S$7,1)),"▼",""))
A38: =IF($B38="","","Livros") | B38: =IF(Livros!B13="","",Livros!B13) | C38: =IF($B38="","",IF(Livros!R13="","",Livros!R13)) | D38: =IF($B38="","",IF(Livros!I13="","",Livros!I13)) | E38: =IF($B38="","",IF(Livros!J13="","",Livros!J13)) | F38: ="" | G38: =IF($B38="","",Livros!M13) | H38: =IF(OR($B38="",$F38=""),"",IF(AND($F38>=H$7,$F38<EDATE(H$7,1)),"▼","")) | I38: =IF(OR($B38="",$F38=""),"",IF(AND($F38>=I$7,$F38<EDATE(I$7,1)),"▼","")) | J38: =IF(OR($B38="",$F38=""),"",IF(AND($F38>=J$7,$F38<EDATE(J$7,1)),"▼","")) | K38: =IF(OR($B38="",$F38=""),"",IF(AND($F38>=K$7,$F38<EDATE(K$7,1)),"▼","")) | L38: =IF(OR($B38="",$F38=""),"",IF(AND($F38>=L$7,$F38<EDATE(L$7,1)),"▼","")) | M38: =IF(OR($B38="",$F38=""),"",IF(AND($F38>=M$7,$F38<EDATE(M$7,1)),"▼","")) | N38: =IF(OR($B38="",$F38=""),"",IF(AND($F38>=N$7,$F38<EDATE(N$7,1)),"▼","")) | O38: =IF(OR($B38="",$F38=""),"",IF(AND($F38>=O$7,$F38<EDATE(O$7,1)),"▼","")) | ... S38: =IF(OR($B38="",$F38=""),"",IF(AND($F38>=S$7,$F38<EDATE(S$7,1)),"▼",""))
A39: =IF($B39="","","Livros") | B39: =IF(Livros!B14="","",Livros!B14) | C39: =IF($B39="","",IF(Livros!R14="","",Livros!R14)) | D39: =IF($B39="","",IF(Livros!I14="","",Livros!I14)) | E39: =IF($B39="","",IF(Livros!J14="","",Livros!J14)) | F39: ="" | G39: =IF($B39="","",Livros!M14) | H39: =IF(OR($B39="",$F39=""),"",IF(AND($F39>=H$7,$F39<EDATE(H$7,1)),"▼","")) | I39: =IF(OR($B39="",$F39=""),"",IF(AND($F39>=I$7,$F39<EDATE(I$7,1)),"▼","")) | J39: =IF(OR($B39="",$F39=""),"",IF(AND($F39>=J$7,$F39<EDATE(J$7,1)),"▼","")) | K39: =IF(OR($B39="",$F39=""),"",IF(AND($F39>=K$7,$F39<EDATE(K$7,1)),"▼","")) | L39: =IF(OR($B39="",$F39=""),"",IF(AND($F39>=L$7,$F39<EDATE(L$7,1)),"▼","")) | M39: =IF(OR($B39="",$F39=""),"",IF(AND($F39>=M$7,$F39<EDATE(M$7,1)),"▼","")) | N39: =IF(OR($B39="",$F39=""),"",IF(AND($F39>=N$7,$F39<EDATE(N$7,1)),"▼","")) | O39: =IF(OR($B39="",$F39=""),"",IF(AND($F39>=O$7,$F39<EDATE(O$7,1)),"▼","")) | ... S39: =IF(OR($B39="",$F39=""),"",IF(AND($F39>=S$7,$F39<EDATE(S$7,1)),"▼",""))
A40: =IF($B40="","","Livros") | B40: =IF(Livros!B15="","",Livros!B15) | C40: =IF($B40="","",IF(Livros!R15="","",Livros!R15)) | D40: =IF($B40="","",IF(Livros!I15="","",Livros!I15)) | E40: =IF($B40="","",IF(Livros!J15="","",Livros!J15)) | F40: ="" | G40: =IF($B40="","",Livros!M15) | H40: =IF(OR($B40="",$F40=""),"",IF(AND($F40>=H$7,$F40<EDATE(H$7,1)),"▼","")) | I40: =IF(OR($B40="",$F40=""),"",IF(AND($F40>=I$7,$F40<EDATE(I$7,1)),"▼","")) | J40: =IF(OR($B40="",$F40=""),"",IF(AND($F40>=J$7,$F40<EDATE(J$7,1)),"▼","")) | K40: =IF(OR($B40="",$F40=""),"",IF(AND($F40>=K$7,$F40<EDATE(K$7,1)),"▼","")) | L40: =IF(OR($B40="",$F40=""),"",IF(AND($F40>=L$7,$F40<EDATE(L$7,1)),"▼","")) | M40: =IF(OR($B40="",$F40=""),"",IF(AND($F40>=M$7,$F40<EDATE(M$7,1)),"▼","")) | N40: =IF(OR($B40="",$F40=""),"",IF(AND($F40>=N$7,$F40<EDATE(N$7,1)),"▼","")) | O40: =IF(OR($B40="",$F40=""),"",IF(AND($F40>=O$7,$F40<EDATE(O$7,1)),"▼","")) | ... S40: =IF(OR($B40="",$F40=""),"",IF(AND($F40>=S$7,$F40<EDATE(S$7,1)),"▼",""))
A41: =IF($B41="","","Livros") | B41: =IF(Livros!B16="","",Livros!B16) | C41: =IF($B41="","",IF(Livros!R16="","",Livros!R16)) | D41: =IF($B41="","",IF(Livros!I16="","",Livros!I16)) | E41: =IF($B41="","",IF(Livros!J16="","",Livros!J16)) | F41: ="" | G41: =IF($B41="","",Livros!M16) | H41: =IF(OR($B41="",$F41=""),"",IF(AND($F41>=H$7,$F41<EDATE(H$7,1)),"▼","")) | I41: =IF(OR($B41="",$F41=""),"",IF(AND($F41>=I$7,$F41<EDATE(I$7,1)),"▼","")) | J41: =IF(OR($B41="",$F41=""),"",IF(AND($F41>=J$7,$F41<EDATE(J$7,1)),"▼","")) | K41: =IF(OR($B41="",$F41=""),"",IF(AND($F41>=K$7,$F41<EDATE(K$7,1)),"▼","")) | L41: =IF(OR($B41="",$F41=""),"",IF(AND($F41>=L$7,$F41<EDATE(L$7,1)),"▼","")) | M41: =IF(OR($B41="",$F41=""),"",IF(AND($F41>=M$7,$F41<EDATE(M$7,1)),"▼","")) | N41: =IF(OR($B41="",$F41=""),"",IF(AND($F41>=N$7,$F41<EDATE(N$7,1)),"▼","")) | O41: =IF(OR($B41="",$F41=""),"",IF(AND($F41>=O$7,$F41<EDATE(O$7,1)),"▼","")) | ... S41: =IF(OR($B41="",$F41=""),"",IF(AND($F41>=S$7,$F41<EDATE(S$7,1)),"▼",""))
A42: =IF($B42="","","Livros") | B42: =IF(Livros!B17="","",Livros!B17) | C42: =IF($B42="","",IF(Livros!R17="","",Livros!R17)) | D42: =IF($B42="","",IF(Livros!I17="","",Livros!I17)) | E42: =IF($B42="","",IF(Livros!J17="","",Livros!J17)) | F42: ="" | G42: =IF($B42="","",Livros!M17) | H42: =IF(OR($B42="",$F42=""),"",IF(AND($F42>=H$7,$F42<EDATE(H$7,1)),"▼","")) | I42: =IF(OR($B42="",$F42=""),"",IF(AND($F42>=I$7,$F42<EDATE(I$7,1)),"▼","")) | J42: =IF(OR($B42="",$F42=""),"",IF(AND($F42>=J$7,$F42<EDATE(J$7,1)),"▼","")) | K42: =IF(OR($B42="",$F42=""),"",IF(AND($F42>=K$7,$F42<EDATE(K$7,1)),"▼","")) | L42: =IF(OR($B42="",$F42=""),"",IF(AND($F42>=L$7,$F42<EDATE(L$7,1)),"▼","")) | M42: =IF(OR($B42="",$F42=""),"",IF(AND($F42>=M$7,$F42<EDATE(M$7,1)),"▼","")) | N42: =IF(OR($B42="",$F42=""),"",IF(AND($F42>=N$7,$F42<EDATE(N$7,1)),"▼","")) | O42: =IF(OR($B42="",$F42=""),"",IF(AND($F42>=O$7,$F42<EDATE(O$7,1)),"▼","")) | ... S42: =IF(OR($B42="",$F42=""),"",IF(AND($F42>=S$7,$F42<EDATE(S$7,1)),"▼",""))
A43: =IF($B43="","","Livros") | B43: =IF(Livros!B18="","",Livros!B18) | C43: =IF($B43="","",IF(Livros!R18="","",Livros!R18)) | D43: =IF($B43="","",IF(Livros!I18="","",Livros!I18)) | E43: =IF($B43="","",IF(Livros!J18="","",Livros!J18)) | F43: ="" | G43: =IF($B43="","",Livros!M18) | H43: =IF(OR($B43="",$F43=""),"",IF(AND($F43>=H$7,$F43<EDATE(H$7,1)),"▼","")) | I43: =IF(OR($B43="",$F43=""),"",IF(AND($F43>=I$7,$F43<EDATE(I$7,1)),"▼","")) | J43: =IF(OR($B43="",$F43=""),"",IF(AND($F43>=J$7,$F43<EDATE(J$7,1)),"▼","")) | K43: =IF(OR($B43="",$F43=""),"",IF(AND($F43>=K$7,$F43<EDATE(K$7,1)),"▼","")) | L43: =IF(OR($B43="",$F43=""),"",IF(AND($F43>=L$7,$F43<EDATE(L$7,1)),"▼","")) | M43: =IF(OR($B43="",$F43=""),"",IF(AND($F43>=M$7,$F43<EDATE(M$7,1)),"▼","")) | N43: =IF(OR($B43="",$F43=""),"",IF(AND($F43>=N$7,$F43<EDATE(N$7,1)),"▼","")) | O43: =IF(OR($B43="",$F43=""),"",IF(AND($F43>=O$7,$F43<EDATE(O$7,1)),"▼","")) | ... S43: =IF(OR($B43="",$F43=""),"",IF(AND($F43>=S$7,$F43<EDATE(S$7,1)),"▼",""))
...

Sheet Metas de Estudo
A1: METAS DE ESTUDO
A2: Defina metas mensais de horas, acompanhe o ritmo e veja seu mapa de calor | N2: ← Voltar ao Início
B5: Mês de referência: | C5: 46296 | D5: 1º dia (auto): | E5: =DATE(YEAR($C$5),MONTH($C$5),1) -> 46296 | F5: % do mês decorrido: | G5: =MAX(0,MIN(1,(TODAY()-$E$5+1)/(EOMONTH($E$5,0)-$E$5+1))) -> 0.096774194 | H5: ← digite qualquer data do mês
B7: HORAS NO MÊS | D7: META DO MÊS | F7: % DA META | G7: DIAS ESTUDADOS
B8: =D18 -> 4.5 | D8: =C18 -> 73 | F8: =E18 -> 0.061643836 | G8: =COUNTIF(J14:P14,">0")+COUNTIF(J16:P16,">0")+COUNTIF(J18:P18,">0")+COUNTIF(J20:P20,">0")+COUNTIF(J22:P22,">0")+COUNTIF(J24:P24,">0") -> 3
B11: METAS POR CATEGORIA | J11: MAPA DE CALOR DO MÊS
B12: Categoria | C12: Meta (h) | D12: Realizado (h) | E12: % da meta | F12: Progresso | G12: Faltam (h) | H12: Ritmo | J12: Seg | K12: Ter | L12: Qua | M12: Qui | N12: Sex | O12: Sáb | P12: Dom
B13: =Listas!$E$6 -> Pós-graduação | C13: 20 | D13: =SUMIFS('Diário de Estudo'!$D$7:$D$506,'Diário de Estudo'!$B$7:$B$506,$B13,'Diário de Estudo'!$A$7:$A$506,">="&$E$5,'Diário de Estudo'!$A$7:$A$506,"<"&EDATE($E$5,1)) -> 2 | E13: =IF(C13=0,0,D13/C13) -> 0.1 | F13: =REPT("█",MIN(10,ROUND(E13*10,0)))&REPT("░",10-MIN(10,ROUND(E13*10,0))) -> █░░░░░░░░░ | G13: =MAX(0,C13-D13) -> 18 | H13: =IF(C13=0,"—",IF(D13>=C13,"Meta batida",IF(D13>=C13*$G$5,"No ritmo","Abaixo do ritmo"))) -> No ritmo | J13: =IF(MONTH($E$5-WEEKDAY($E$5,2)+1+0)=MONTH($E$5),$E$5-WEEKDAY($E$5,2)+1+0,"") | K13: =IF(MONTH($E$5-WEEKDAY($E$5,2)+1+1)=MONTH($E$5),$E$5-WEEKDAY($E$5,2)+1+1,"") | L13: =IF(MONTH($E$5-WEEKDAY($E$5,2)+1+2)=MONTH($E$5),$E$5-WEEKDAY($E$5,2)+1+2,"") | M13: =IF(MONTH($E$5-WEEKDAY($E$5,2)+1+3)=MONTH($E$5),$E$5-WEEKDAY($E$5,2)+1+3,"") -> 46296 | N13: =IF(MONTH($E$5-WEEKDAY($E$5,2)+1+4)=MONTH($E$5),$E$5-WEEKDAY($E$5,2)+1+4,"") -> 46297 | O13: =IF(MONTH($E$5-WEEKDAY($E$5,2)+1+5)=MONTH($E$5),$E$5-WEEKDAY($E$5,2)+1+5,"") -> 46298 | P13: =IF(MONTH($E$5-WEEKDAY($E$5,2)+1+6)=MONTH($E$5),$E$5-WEEKDAY($E$5,2)+1+6,"") -> 46299
B14: =Listas!$E$7 -> Concurso | C14: 20 | D14: =SUMIFS('Diário de Estudo'!$D$7:$D$506,'Diário de Estudo'!$B$7:$B$506,$B14,'Diário de Estudo'!$A$7:$A$506,">="&$E$5,'Diário de Estudo'!$A$7:$A$506,"<"&EDATE($E$5,1)) -> 0 | E14: =IF(C14=0,0,D14/C14) -> 0 | F14: =REPT("█",MIN(10,ROUND(E14*10,0)))&REPT("░",10-MIN(10,ROUND(E14*10,0))) -> ░░░░░░░░░░ | G14: =MAX(0,C14-D14) -> 20 | H14: =IF(C14=0,"—",IF(D14>=C14,"Meta batida",IF(D14>=C14*$G$5,"No ritmo","Abaixo do ritmo"))) -> Abaixo do ritmo | J14: =IF(J13="","",SUMIFS('Diário de Estudo'!$D$7:$D$506,'Diário de Estudo'!$A$7:$A$506,J13)) | K14: =IF(K13="","",SUMIFS('Diário de Estudo'!$D$7:$D$506,'Diário de Estudo'!$A$7:$A$506,K13)) | L14: =IF(L13="","",SUMIFS('Diário de Estudo'!$D$7:$D$506,'Diário de Estudo'!$A$7:$A$506,L13)) | M14: =IF(M13="","",SUMIFS('Diário de Estudo'!$D$7:$D$506,'Diário de Estudo'!$A$7:$A$506,M13)) -> 2 | N14: =IF(N13="","",SUMIFS('Diário de Estudo'!$D$7:$D$506,'Diário de Estudo'!$A$7:$A$506,N13)) -> 1.5 | O14: =IF(O13="","",SUMIFS('Diário de Estudo'!$D$7:$D$506,'Diário de Estudo'!$A$7:$A$506,O13)) -> 1 | P14: =IF(P13="","",SUMIFS('Diário de Estudo'!$D$7:$D$506,'Diário de Estudo'!$A$7:$A$506,P13)) -> 0
B15: =Listas!$E$8 -> Livros | C15: 8 | D15: =SUMIFS('Diário de Estudo'!$D$7:$D$506,'Diário de Estudo'!$B$7:$B$506,$B15,'Diário de Estudo'!$A$7:$A$506,">="&$E$5,'Diário de Estudo'!$A$7:$A$506,"<"&EDATE($E$5,1)) -> 1 | E15: =IF(C15=0,0,D15/C15) -> 0.125 | F15: =REPT("█",MIN(10,ROUND(E15*10,0)))&REPT("░",10-MIN(10,ROUND(E15*10,0))) -> █░░░░░░░░░ | G15: =MAX(0,C15-D15) -> 7 | H15: =IF(C15=0,"—",IF(D15>=C15,"Meta batida",IF(D15>=C15*$G$5,"No ritmo","Abaixo do ritmo"))) -> No ritmo | J15: =IF(MONTH($E$5-WEEKDAY($E$5,2)+1+7)=MONTH($E$5),$E$5-WEEKDAY($E$5,2)+1+7,"") -> 46300 | K15: =IF(MONTH($E$5-WEEKDAY($E$5,2)+1+8)=MONTH($E$5),$E$5-WEEKDAY($E$5,2)+1+8,"") -> 46301 | L15: =IF(MONTH($E$5-WEEKDAY($E$5,2)+1+9)=MONTH($E$5),$E$5-WEEKDAY($E$5,2)+1+9,"") -> 46302 | M15: =IF(MONTH($E$5-WEEKDAY($E$5,2)+1+10)=MONTH($E$5),$E$5-WEEKDAY($E$5,2)+1+10,"") -> 46303 | N15: =IF(MONTH($E$5-WEEKDAY($E$5,2)+1+11)=MONTH($E$5),$E$5-WEEKDAY($E$5,2)+1+11,"") -> 46304 | O15: =IF(MONTH($E$5-WEEKDAY($E$5,2)+1+12)=MONTH($E$5),$E$5-WEEKDAY($E$5,2)+1+12,"") -> 46305 | P15: =IF(MONTH($E$5-WEEKDAY($E$5,2)+1+13)=MONTH($E$5),$E$5-WEEKDAY($E$5,2)+1+13,"") -> 46306
B16: =Listas!$E$9 -> Cursos IA | C16: 15 | D16: =SUMIFS('Diário de Estudo'!$D$7:$D$506,'Diário de Estudo'!$B$7:$B$506,$B16,'Diário de Estudo'!$A$7:$A$506,">="&$E$5,'Diário de Estudo'!$A$7:$A$506,"<"&EDATE($E$5,1)) -> 1.5 | E16: =IF(C16=0,0,D16/C16) -> 0.1 | F16: =REPT("█",MIN(10,ROUND(E16*10,0)))&REPT("░",10-MIN(10,ROUND(E16*10,0))) -> █░░░░░░░░░ | G16: =MAX(0,C16-D16) -> 13.5 | H16: =IF(C16=0,"—",IF(D16>=C16,"Meta batida",IF(D16>=C16*$G$5,"No ritmo","Abaixo do ritmo"))) -> No ritmo | J16: =IF(J15="","",SUMIFS('Diário de Estudo'!$D$7:$D$506,'Diário de Estudo'!$A$7:$A$506,J15)) -> 0 | K16: =IF(K15="","",SUMIFS('Diário de Estudo'!$D$7:$D$506,'Diário de Estudo'!$A$7:$A$506,K15)) -> 0 | L16: =IF(L15="","",SUMIFS('Diário de Estudo'!$D$7:$D$506,'Diário de Estudo'!$A$7:$A$506,L15)) -> 0 | M16: =IF(M15="","",SUMIFS('Diário de Estudo'!$D$7:$D$506,'Diário de Estudo'!$A$7:$A$506,M15)) -> 0 | N16: =IF(N15="","",SUMIFS('Diário de Estudo'!$D$7:$D$506,'Diário de Estudo'!$A$7:$A$506,N15)) -> 0 | O16: =IF(O15="","",SUMIFS('Diário de Estudo'!$D$7:$D$506,'Diário de Estudo'!$A$7:$A$506,O15)) -> 0 | P16: =IF(P15="","",SUMIFS('Diário de Estudo'!$D$7:$D$506,'Diário de Estudo'!$A$7:$A$506,P15)) -> 0
B17: =Listas!$E$10 -> Renda Extra | C17: 10 | D17: =SUMIFS('Diário de Estudo'!$D$7:$D$506,'Diário de Estudo'!$B$7:$B$506,$B17,'Diário de Estudo'!$A$7:$A$506,">="&$E$5,'Diário de Estudo'!$A$7:$A$506,"<"&EDATE($E$5,1)) -> 0 | E17: =IF(C17=0,0,D17/C17) -> 0 | F17: =REPT("█",MIN(10,ROUND(E17*10,0)))&REPT("░",10-MIN(10,ROUND(E17*10,0))) -> ░░░░░░░░░░ | G17: =MAX(0,C17-D17) -> 10 | H17: =IF(C17=0,"—",IF(D17>=C17,"Meta batida",IF(D17>=C17*$G$5,"No ritmo","Abaixo do ritmo"))) -> Abaixo do ritmo | J17: =IF(MONTH($E$5-WEEKDAY($E$5,2)+1+14)=MONTH($E$5),$E$5-WEEKDAY($E$5,2)+1+14,"") -> 46307 | K17: =IF(MONTH($E$5-WEEKDAY($E$5,2)+1+15)=MONTH($E$5),$E$5-WEEKDAY($E$5,2)+1+15,"") -> 46308 | L17: =IF(MONTH($E$5-WEEKDAY($E$5,2)+1+16)=MONTH($E$5),$E$5-WEEKDAY($E$5,2)+1+16,"") -> 46309 | M17: =IF(MONTH($E$5-WEEKDAY($E$5,2)+1+17)=MONTH($E$5),$E$5-WEEKDAY($E$5,2)+1+17,"") -> 46310 | N17: =IF(MONTH($E$5-WEEKDAY($E$5,2)+1+18)=MONTH($E$5),$E$5-WEEKDAY($E$5,2)+1+18,"") -> 46311 | O17: =IF(MONTH($E$5-WEEKDAY($E$5,2)+1+19)=MONTH($E$5),$E$5-WEEKDAY($E$5,2)+1+19,"") -> 46312 | P17: =IF(MONTH($E$5-WEEKDAY($E$5,2)+1+20)=MONTH($E$5),$E$5-WEEKDAY($E$5,2)+1+20,"") -> 46313
B18: TOTAL | C18: =SUM(C13:C17) -> 73 | D18: =SUM(D13:D17) -> 4.5 | E18: =IF(C18=0,0,D18/C18) -> 0.061643836 | F18: =REPT("█",MIN(10,ROUND(E18*10,0)))&REPT("░",10-MIN(10,ROUND(E18*10,0))) -> █░░░░░░░░░ | G18: =MAX(0,C18-D18) -> 68.5 | H18: =IF(C18=0,"—",IF(D18>=C18,"Meta batida",IF(D18>=C18*$G$5,"No ritmo","Abaixo do ritmo"))) -> Abaixo do ritmo | J18: =IF(J17="","",SUMIFS('Diário de Estudo'!$D$7:$D$506,'Diário de Estudo'!$A$7:$A$506,J17)) -> 0 | K18: =IF(K17="","",SUMIFS('Diário de Estudo'!$D$7:$D$506,'Diário de Estudo'!$A$7:$A$506,K17)) -> 0 | L18: =IF(L17="","",SUMIFS('Diário de Estudo'!$D$7:$D$506,'Diário de Estudo'!$A$7:$A$506,L17)) -> 0 | M18: =IF(M17="","",SUMIFS('Diário de Estudo'!$D$7:$D$506,'Diário de Estudo'!$A$7:$A$506,M17)) -> 0 | N18: =IF(N17="","",SUMIFS('Diário de Estudo'!$D$7:$D$506,'Diário de Estudo'!$A$7:$A$506,N17)) -> 0 | O18: =IF(O17="","",SUMIFS('Diário de Estudo'!$D$7:$D$506,'Diário de Estudo'!$A$7:$A$506,O17)) -> 0 | P18: =IF(P17="","",SUMIFS('Diário de Estudo'!$D$7:$D$506,'Diário de Estudo'!$A$7:$A$506,P17)) -> 0
